#VRML_SIM R2019a utf8
WorldInfo {
}
Viewpoint {
  orientation -0.14677587975967846 -0.9740617276046908 -0.17222250705566244 1.7558913776799674
  position -2.0474135075034363 1.7792506113279678 -0.1493893841585405
}
TexturedBackground {
}
TexturedBackgroundLight {
}
Floor {
}
Solid {
  translation 0 0.1375 0
  children [
    DEF SH_BASE Shape {
      appearance PBRAppearance {
      }
      geometry DEF GEO_BASE Cylinder {
        height 0.275
        radius 0.118
      }
    }
    DEF HG_JOINT_1 HingeJoint {
      jointParameters DEF HG_1 HingeJointParameters {
        axis 0 1 0
        anchor 0 0.182 0
        minStop -2.97
        maxStop 2.97
      }
      endPoint DEF JOINT_1 Solid {
        translation 0 0.18069424585194277 3.5782965436201297e-09
        rotation 1 0 0 7.130232879935179e-06
        children [
          DEF GR_JOINT_1 Group {
            children [
              DEF BASE_1 Shape {
                appearance DEF BASE_APP PBRAppearance {
                  baseColor 0.7294117647058823 0.7411764705882353 0.7137254901960784
                  metalness 0
                }
                geometry Box {
                  size 0.118 0.08 0.118
                }
              }
              DEF BASE_LEFT Transform {
                translation 0 0.060079613646983415 -0.09995218869053943
                rotation 1 0 0 -1.57
                children [
                  DEF BASE_LEFT Shape {
                    appearance USE BASE_APP
                    geometry Box {
                      size 0.125 0.08 0.2
                    }
                  }
                ]
              }
              DEF BASE_RIGHT Transform {
                translation 0 0.05992034830483674 0.10004774789582749
                rotation 1 0 0 -1.57
                children [
                  DEF BASE_RIGTH Shape {
                    appearance USE BASE_APP
                    geometry Box {
                      size 0.125 0.08 0.2
                    }
                  }
                ]
              }
            ]
          }
          DEF HG_2 HingeJoint {
            jointParameters DEF JOINT_2 HingeJointParameters {
              axis 0 0 1
              anchor 0 0.135 0
              minStop -3.32
              maxStop 0.785
            }
            endPoint DEF JOINT_2 Solid {
              translation 0 0.26999997582218643 -0.00011426293731127918
              rotation -0.9999999999999999 0 0 0.00042319607644596277
              children [
                DEF GR_JOINT_2 Group {
                  children [
                    DEF LINK_1 Shape {
                      appearance USE BASE_APP
                      geometry Box {
                        size 0.11 0.38 0.11
                      }
                    }
                    DEF LINK_2_RIGHT Transform {
                      translation 0 0.28 -0.10999999999999999
                      children [
                        DEF LINK_2 Shape {
                          appearance USE BASE_APP
                          geometry Box {
                            size 0.11 0.28 0.11
                          }
                        }
                      ]
                    }
                    DEF LINK_3 Transform {
                      translation 0 0.28 0.10999999999999999
                      children [
                        DEF LINK_2 Shape {
                          appearance USE BASE_APP
                          geometry Box {
                            size 0.11 0.28 0.11
                          }
                        }
                      ]
                    }
                  ]
                }
                DEF HG_3 HingeJoint {
                  jointParameters DEF JOINT_3 HingeJointParameters {
                    axis 0 0 1
                    anchor 0 0.3 0
                    minStop 2.09
                    maxStop 2.726
                  }
                  endPoint DEF JOINT_3 Solid {
                    rotation 0 0 1 0
                    children [
                      DEF DEF_JOINT_3 Group {
                        children [
                          DEF LINK_3 Transform {
                            translation 0 0.4500000000000002 0
                            children [
                              DEF LINK_3 Shape {
                                appearance USE BASE_APP
                                geometry Box {
                                  size 0.11 0.28 0.11
                                }
                              }
                            ]
                          }
                        ]
                      }
                      DEF HG_4 HingeJoint {
                        jointParameters DEF JOINT_4 HingeJointParameters {
                          axis 0 1 0
                          anchor 0 0.32 0
                          minStop -3.229
                          maxStop 3.229
                        }
                        endPoint DEF JOINT_4 Solid {
                          children [
                            DEF GR_JOINT_4 Group {
                              children [
                                DEF LINK_3_LEFT Transform {
                                  translation 0 0.7200000000000004 0.09999999999999999
                                  children [
                                    DEF LINK_3_LEFT Shape {
                                      appearance USE BASE_APP
                                      geometry Box {
                                        size 0.11 0.11 0.11
                                      }
                                    }
                                  ]
                                }
                                DEF LINK_3_RIGHT Transform {
                                  translation 0 0.7200000000000004 -0.09999999999999999
                                  children [
                                    DEF LINK_3_LEFT Shape {
                                      appearance USE BASE_APP
                                      geometry Box {
                                        size 0.11 0.11 0.11
                                      }
                                    }
                                  ]
                                }
                                DEF LINK_3 Transform {
                                  translation 0 0.6500000000000004 3.469446951953614e-18
                                  children [
                                    DEF LINK_3_LEFT Shape {
                                      appearance USE BASE_APP
                                      geometry Box {
                                        size 0.11 0.12 0.11
                                      }
                                    }
                                  ]
                                }
                              ]
                            }
                            DEF HG_JOINT_5 Hinge2Joint {
                              jointParameters DEF JOINT_1 HingeJointParameters {
                                axis 0 1 0
                                anchor 0 0.4 0
                              }
                              jointParameters2 JointParameters {
                              }
                              endPoint DEF LINK_5 Solid {
                                translation 0 0.8100000000000003 0
                                children [
                                  Shape {
                                    appearance PBRAppearance {
                                      baseColor 0 0 0
                                    }
                                    geometry DEF GEO_LINK_5 Cylinder {
                                      height 0.13
                                      radius 0.05
                                    }
                                  }
                                ]
                                boundingObject USE GEO_LINK_5
                                physics Physics {
                                }
                              }
                            }
                          ]
                        }
                      }
                    ]
                    boundingObject USE DEF_JOINT_3
                    physics Physics {
                    }
                  }
                }
              ]
              boundingObject USE GR_JOINT_2
              physics Physics {
              }
            }
          }
        ]
        boundingObject USE GR_JOINT_1
        physics Physics {
          density -1
          mass 55
        }
      }
    }
  ]
  name "solid(1)"
}
