#VRML_SIM R2019a utf8
WorldInfo {
}
Viewpoint {
  orientation -0.8080163788941251 0.5555560492139093 0.19613007831706541 0.8238372907547992
  position 0.7139211286168112 1.3667502161226293 0.9232468930768699
}
TexturedBackground {
}
TexturedBackgroundLight {
}
Floor {
}
Solid {
  translation 0 0.09999999999999999 0
  children [
    DEF KUKA Group {
      children [
        DEF CYL_BASE Shape {
          appearance PBRAppearance {
          }
          geometry Cylinder {
            height 0.2
            radius 0.05
          }
        }
        DEF STRUC_1 Transform {
          translation 0 0.10999999999999993 0
          children [
            HingeJoint {
              jointParameters DEF HINGE_ROT_1 HingeJointParameters {
                axis 0 1 0
              }
              endPoint DEF SOL_1 Solid {
                translation 0 -3.920114351962933e-06 0
                children [
                  DEF STRUC_1 Group {
                    children [
                      Shape {
                        appearance DEF SOLD_1 PBRAppearance {
                          metalness 0
                        }
                        geometry DEF GEO_1 Box {
                          size 0.1 0.025 0.1
                        }
                      }
                      DEF RIGHT_SOLID Solid {
                        translation 0 0.04 -0.038
                        children [
                          Shape {
                            appearance PBRAppearance {
                              metalness 0
                            }
                            geometry DEF RIGHT_SOLID Box {
                              size 0.1 0.1 0.025
                            }
                          }
                        ]
                        name "solid(3)"
                        boundingObject USE RIGHT_SOLID
                        physics Physics {
                        }
                      }
                      DEF LEFT_SOLID Solid {
                        translation 0 0.04 0.04
                        children [
                          Shape {
                            appearance PBRAppearance {
                              metalness 0
                            }
                            geometry DEF LEFT_SOLID Box {
                              size 0.1 0.1 0.025
                            }
                          }
                        ]
                        name "solid(4)"
                        boundingObject USE LEFT_SOLID
                        physics Physics {
                        }
                      }
                    ]
                  }
                  DEF LINK_1 HingeJoint {
                    jointParameters HingeJointParameters {
                      axis 0 0 1
                      anchor -0.000102266 0.05 0
                    }
                    endPoint Solid {
                      translation -0.0001022657132465159 0.17999997094923076 0
                      rotation 0 0 1 0.0005681428817262297
                      children [
                        DEF link_1 Group {
                          children [
                            Shape {
                              appearance PBRAppearance {
                                metalness 0
                              }
                              geometry DEF LINK_1 Box {
                                size 0.06 0.25 0.05
                              }
                            }
                            DEF RIGHT_SOLID Solid {
                              translation 0 0.13999999999999996 -0.038
                              children [
                                Shape {
                                  appearance PBRAppearance {
                                    metalness 0
                                  }
                                  geometry DEF RIGHT_SOLID Box {
                                    size 0.1 0.15 0.025
                                  }
                                }
                              ]
                              name "solid(1)"
                              boundingObject USE RIGHT_SOLID
                              physics Physics {
                              }
                            }
                            DEF LEFT_SOLID Solid {
                              translation 0 0.13999999999999996 0.03200000000000001
                              children [
                                Shape {
                                  appearance PBRAppearance {
                                    metalness 0
                                  }
                                  geometry DEF RIGHT_SOLID Box {
                                    size 0.1 0.15 0.025
                                  }
                                }
                              ]
                              name "solid(2)"
                              boundingObject USE RIGHT_SOLID
                              physics Physics {
                              }
                            }
                          ]
                        }
                        DEF link_2 HingeJoint {
                          jointParameters HingeJointParameters {
                            axis 0 0 1
                            anchor -3.29175e-05 0.14 0
                          }
                          endPoint Solid {
                            translation -3.29174848803411e-05 0.2837619677698608 0
                            rotation 0 0 1 0
                            children [
                              Shape {
                                appearance PBRAppearance {
                                  metalness 0
                                }
                                geometry DEF LINK_2 Box {
                                  size 0.06 0.25 0.05
                                }
                              }
                            ]
                            boundingObject USE LINK_2
                            physics Physics {
                            }
                          }
                        }
                        DEF link_3 HingeJoint {
                          jointParameters HingeJointParameters {
                          }
                          endPoint Solid {
                            translation 0 0.43000000000000016 0
                            children [
                              Shape {
                                geometry DEF CYL Cylinder {
                                  height 0.1
                                  radius 0.03
                                }
                              }
                            ]
                            name "solid(3)"
                            boundingObject USE CYL
                            physics Physics {
                            }
                          }
                        }
                      ]
                      boundingObject DEF LINK_1 Box {
                        size 0.06 0.25 0.05
                      }
                      physics Physics {
                      }
                    }
                  }
                ]
                boundingObject USE GEO_1
                physics Physics {
                }
              }
            }
          ]
        }
      ]
    }
  ]
  boundingObject USE GEO_1
}
