#VRML_SIM R2019a utf8
WorldInfo {
}
Viewpoint {
  orientation -0.12884847797162222 -0.9676272084044578 -0.21701533420427288 2.098662038906867
  position -1.93684708085525 1.6143642518256263 -0.968980472212597
}
TexturedBackground {
}
TexturedBackgroundLight {
}
Floor {
}
Robot {
  translation 0 0.138 0
  children [
    DEF SH_BASE Shape {
      appearance PBRAppearance {
      }
      geometry DEF GEO_BASE Cylinder {
        height 0.275
        radius 0.118
      }
    }
    DEF HG_JOINT_1 HingeJoint {
      jointParameters DEF HG_1 HingeJointParameters {
        axis 0 1 0
        anchor 0 0.182 0
        minStop -2.97
        maxStop 2.97
      }
      device [
        RotationalMotor {
          name "servo_1"
          minPosition -2.97
          maxPosition 2.97
        }
      ]
      endPoint DEF JOINT_1 Solid {
        translation 0 0.18069424585194277 3.5782965436201297e-09
        rotation 1 0 0 7.130232879935179e-06
        children [
          DEF GR_JOINT_1 Group {
            children [
              DEF BASE_1 Shape {
                appearance DEF BASE_APP PBRAppearance {
                  baseColor 0.7294117647058823 0.7411764705882353 0.7137254901960784
                  metalness 0
                }
                geometry Box {
                  size 0.118 0.08 0.118
                }
              }
              DEF BASE_LEFT Transform {
                translation 0 0.060079613646983415 -0.09995218869053943
                rotation 1 0 0 -1.57
                children [
                  DEF BASE_LEFT Shape {
                    appearance USE BASE_APP
                    geometry Box {
                      size 0.125 0.08 0.2
                    }
                  }
                ]
              }
              DEF BASE_RIGHT Transform {
                translation 0 0.05992034830483674 0.10004774789582749
                rotation 1 0 0 -1.57
                children [
                  DEF BASE_RIGTH Shape {
                    appearance USE BASE_APP
                    geometry Box {
                      size 0.125 0.08 0.2
                    }
                  }
                ]
              }
            ]
          }
          DEF HG_2 HingeJoint {
            jointParameters DEF JOINT_2 HingeJointParameters {
              axis 0 0 1
              anchor 0 0.135 0
              minStop -3.32
              maxStop 0.785
            }
            device [
              RotationalMotor {
                name "servo_2"
              }
            ]
            endPoint DEF JOINT_2 Solid {
              translation 0 0.26999997582218643 -0.00011426293731127918
              rotation -1 0 0 0.00042319607644596277
              children [
                DEF GR_JOINT_2 Group {
                  children [
                    DEF LINK_1 Shape {
                      appearance USE BASE_APP
                      geometry Box {
                        size 0.11 0.38 0.11
                      }
                    }
                    DEF LINK_2_RIGHT Transform {
                      translation 0 0.28 -0.10999999999999999
                      children [
                        DEF LINK_2 Shape {
                          appearance USE BASE_APP
                          geometry Box {
                            size 0.11 0.28 0.11
                          }
                        }
                      ]
                    }
                    DEF LINK_3 Transform {
                      translation 0 0.28 0.10999999999999999
                      children [
                        DEF LINK_2 Shape {
                          appearance USE BASE_APP
                          geometry Box {
                            size 0.11 0.28 0.11
                          }
                        }
                      ]
                    }
                  ]
                }
                DEF HG_3 HingeJoint {
                  jointParameters DEF JOINT_3 HingeJointParameters {
                    axis 0 0 1
                    anchor 0 0.3 0
                    minStop -1.09
                    maxStop 1
                  }
                  device [
                    RotationalMotor {
                      name "servo_3"
                    }
                  ]
                  endPoint DEF JOINT_3 Solid {
                    rotation 0 0 1 0
                    children [
                      DEF DEF_JOINT_3 Group {
                        children [
                          DEF LINK_3 Transform {
                            translation 0 0.4500000000000002 0
                            children [
                              DEF LINK_3 Shape {
                                appearance USE BASE_APP
                                geometry Box {
                                  size 0.11 0.28 0.11
                                }
                              }
                            ]
                          }
                        ]
                      }
                      DEF HG_4 HingeJoint {
                        jointParameters DEF JOINT_4 HingeJointParameters {
                          axis 0 1 0
                          anchor 0 0.32 0
                          minStop -3.229
                          maxStop 3.229
                        }
                        device [
                          RotationalMotor {
                            name "servo_4"
                          }
                        ]
                        endPoint DEF JOINT_4 Solid {
                          children [
                            DEF GR_JOINT_4 Group {
                              children [
                                DEF LINK_3_LEFT Transform {
                                  translation 0 0.7200000000000004 0.09999999999999999
                                  children [
                                    DEF LINK_3_LEFT Shape {
                                      appearance USE BASE_APP
                                      geometry Box {
                                        size 0.11 0.11 0.11
                                      }
                                    }
                                  ]
                                }
                                DEF LINK_3_RIGHT Transform {
                                  translation 0 0.7200000000000004 -0.09999999999999999
                                  children [
                                    DEF LINK_3_LEFT Shape {
                                      appearance USE BASE_APP
                                      geometry Box {
                                        size 0.11 0.11 0.11
                                      }
                                    }
                                  ]
                                }
                                DEF LINK_3 Transform {
                                  translation 0 0.6500000000000004 3.469446951953614e-18
                                  children [
                                    DEF LINK_3_LEFT Shape {
                                      appearance USE BASE_APP
                                      geometry Box {
                                        size 0.11 0.12 0.11
                                      }
                                    }
                                  ]
                                }
                                DEF JOINT_5 Transform {
                                  translation 0 0.81 0
                                  children [
                                    DEF HG_JOINT_5 HingeJoint {
                                      jointParameters DEF joint_5 HingeJointParameters {
                                        axis 0 1 0
                                      }
                                      device [
                                        RotationalMotor {
                                          name "servo_5"
                                        }
                                      ]
                                      endPoint DEF LINK_5 Solid {
                                        rotation 0 1 0 3.4957383712816776
                                        children [
                                          Shape {
                                            appearance PBRAppearance {
                                              baseColor 0.1803921568627451 0.20392156862745098 0.21176470588235294
                                            }
                                            geometry DEF CYL_5 Cylinder {
                                              height 0.1
                                              radius 0.05
                                            }
                                          }
                                        ]
                                        boundingObject USE CYL_5
                                        physics Physics {
                                        }
                                      }
                                    }
                                  ]
                                }
                              ]
                            }
                          ]
                          boundingObject USE LINK_3
                          physics Physics {
                          }
                        }
                      }
                    ]
                    boundingObject USE DEF_JOINT_3
                    physics Physics {
                    }
                  }
                }
              ]
              boundingObject USE GR_JOINT_2
              physics Physics {
              }
            }
          }
        ]
        boundingObject USE GR_JOINT_1
        physics Physics {
          density -1
          mass 55
        }
      }
    }
  ]
  controller "robotkuka_Zamudio_Shadeen"
}
